#VRML_SIM R2023b utf8

EXTERNPROTO "https://raw.githubusercontent.com/cyberbotics/webots/R2023b/projects/objects/backgrounds/protos/TexturedBackground.proto"
EXTERNPROTO "https://raw.githubusercontent.com/cyberbotics/webots/R2023b/projects/objects/backgrounds/protos/TexturedBackgroundLight.proto"
EXTERNPROTO "https://raw.githubusercontent.com/cyberbotics/webots/R2023b/projects/objects/floors/protos/RectangleArena.proto"

WorldInfo {
  info [
    "The model of the E-puck robot"
  ]
  title "E-puck simulation"
}
Viewpoint {
  orientation 0.33833806766938457 0.06079968525100531 -0.9390584381385035 3.0121765378222682
  position 5.363141189238739 -0.7757799546351787 4.978684904841154
}
TexturedBackground {
}
TexturedBackgroundLight {
}
RectangleArena {
  translation 0.11 0 0
  floorSize 2.438 4.877
  floorTileSize 2.438 4.877
  floorAppearance Appearance {
    material Material {
    }
    texture ImageTexture {
      url [
        "../Webots/ArenaLowQuality.jpg"
      ]
      repeatS FALSE
      repeatT FALSE
      filtering 0
    }
  }
}
Robot {
  translation 1.17 0.18 0.07
  rotation 0 0 1 1.5708
  children [
    DEF robot_body Group {
      children [
        Solid {
          translation 0 0.08 -0.045
          children [
            DEF caster_shape Shape {
              appearance PBRAppearance {
              }
              geometry Capsule {
                height 0.03
                radius 0.01
              }
            }
          ]
          name "caster_wheel"
          boundingObject USE caster_shape
          physics Physics {
          }
        }
        DEF left_wheel HingeJoint {
          jointParameters HingeJointParameters {
            anchor 0 -0.06 -0.04
          }
          device [
            RotationalMotor {
              name "left_motor"
            }
          ]
          endPoint Solid {
            translation -0.09000000000000008 -0.06000000000000005 -0.04
            rotation 0 -0.9999999999999999 0 1.5707953071795862
            children [
              DEF left_wheel_shape Shape {
                appearance PBRAppearance {
                  baseColor 0.127687 1 0.838727
                }
                geometry Cylinder {
                  height 0.03
                  radius 0.03
                }
              }
            ]
            boundingObject USE left_wheel_shape
            physics Physics {
            }
          }
        }
        DEF right_wheel HingeJoint {
          jointParameters HingeJointParameters {
            anchor 0 -0.06 -0.04
          }
          device [
            RotationalMotor {
              name "right_motor"
            }
          ]
          endPoint Solid {
            translation 0.09 -0.06 -0.04
            rotation 1.4252501626753387e-07 -0.9999999999999796 -1.4367923625557603e-07 1.570795709917693
            children [
              DEF right_wheel_shape Shape {
                appearance PBRAppearance {
                  baseColor 0.127687 1 0.838727
                }
                geometry Cylinder {
                  height 0.03
                  radius 0.03
                }
              }
            ]
            name "solid(1)"
            boundingObject USE right_wheel_shape
            physics Physics {
            }
          }
        }
        DEF body_box Shape {
          appearance PBRAppearance {
          }
          geometry Box {
            size 0.2 0.2 0.1
          }
        }
      ]
    }
  ]
  physics Physics {
  }
  controller "slrc24_controller"
  battery [
    0
  ]
}
Solid {
  translation 0.69 -1.91 0.09
  children [
    DEF pose1_cylinder_shape Shape {
      appearance PBRAppearance {
        metalness 0
      }
      geometry Cylinder {
        height 0.15
        radius 0.03
      }
    }
  ]
  name "pose1_cylinder"
  boundingObject USE pose1_cylinder_shape
  physics Physics {
  }
}
Solid {
  translation -0.64 -1.89 0.1
  children [
    DEF pose2_cuboid_shape Shape {
      appearance PBRAppearance {
        metalness 0
      }
      geometry Box {
        size 0.07 0.07 0.15
      }
    }
  ]
  name "pose2_cuboid"
  boundingObject USE pose2_cuboid_shape
  physics Physics {
  }
}
