#VRML_SIM R2023b utf8

EXTERNPROTO "https://raw.githubusercontent.com/cyberbotics/webots/R2023b/projects/objects/backgrounds/protos/TexturedBackground.proto"
EXTERNPROTO "https://raw.githubusercontent.com/cyberbotics/webots/R2023b/projects/objects/backgrounds/protos/TexturedBackgroundLight.proto"
EXTERNPROTO "https://raw.githubusercontent.com/cyberbotics/webots/R2023b/projects/objects/floors/protos/RectangleArena.proto"

WorldInfo {
  info [
    "The model of the E-puck robot"
  ]
  title "E-puck simulation"
}
Viewpoint {
  orientation -0.3963475933151107 -0.009777755987277417 0.9180484631876321 3.0095766181160886
  position 4.249892240808857 -0.5323489155998936 4.091147708759644
}
TexturedBackground {
}
TexturedBackgroundLight {
}
RectangleArena {
  translation 0.11 0 0
  floorSize 2.438 4.877
  floorTileSize 2.438 4.877
  floorAppearance Appearance {
    material Material {
    }
    texture ImageTexture {
      url [
        "../Webots/ArenaLowQuality.jpg"
      ]
      repeatS FALSE
      repeatT FALSE
      filtering 0
    }
  }
}
Solid {
  translation 0.89 0.94 0.03
  children [
    DEF metal_box_shape Shape {
      appearance PBRAppearance {
      }
      geometry Box {
        size 0.05 0.05 0.05
      }
    }
  ]
  name "metal_box"
  boundingObject USE metal_box_shape
  physics Physics {
  }
}
Solid {
  translation 0.01 -1.82 0.03
  children [
    DEF metal_box_shape Shape {
      appearance PBRAppearance {
      }
      geometry Box {
        size 0.05 0.05 0.05
      }
    }
  ]
  name "metal_box2"
  boundingObject USE metal_box_shape
  physics Physics {
  }
}
Solid {
  translation 0.39 -1.44 0.02
  children [
    DEF non_metal_box Shape {
      appearance PBRAppearance {
        metalness 0
      }
      geometry Box {
        size 0.05 0.05 0.05
      }
    }
  ]
  name "non_metal_box"
  boundingObject USE non_metal_box
  physics Physics {
  }
}
Solid {
  translation -0.36 -1.44 0.02
  children [
    DEF non_metal_box Shape {
      appearance PBRAppearance {
        metalness 0
      }
      geometry Box {
        size 0.05 0.05 0.05
      }
    }
  ]
  name "non_metal_box2"
  boundingObject USE non_metal_box
  physics Physics {
  }
}
Solid {
  translation 0.52 0.56 0.02
  children [
    DEF non_metal_box Shape {
      appearance PBRAppearance {
        metalness 0
      }
      geometry Box {
        size 0.05 0.05 0.05
      }
    }
  ]
  name "non_metal_box3"
  boundingObject USE non_metal_box
  physics Physics {
  }
}
Solid {
  translation 0.52 1.32 0.02
  children [
    DEF non_metal_box Shape {
      appearance PBRAppearance {
        metalness 0
      }
      geometry Box {
        size 0.05 0.05 0.05
      }
    }
  ]
  name "non_metal_box4"
  boundingObject USE non_metal_box
  physics Physics {
  }
}
Robot {
  translation 1.17 0.18 0.07
  rotation 0 0 1 1.5708
  children [
    DEF robot_body Group {
      children [
        DEF LineSensorPanel Group {
          children [
            DEF lineSensor0 DistanceSensor {
              translation -0.04 0.1 -0.05
              rotation 0 1 0 1.5708
              name "lineSensor0"
              type "infra-red"
            }
            DEF lineSensor1 DistanceSensor {
              translation -0.03 0.1 -0.05
              rotation 0 1 0 1.5708
              name "lineSensor1"
              type "infra-red"
            }
            DEF lineSensor2 DistanceSensor {
              translation -0.02 0.1 -0.05
              rotation 0 1 0 1.5708
              name "lineSensor2"
              type "infra-red"
            }
            DEF lineSensor3 DistanceSensor {
              translation -0.01 0.1 -0.05
              rotation 0 1 0 1.5708
              name "lineSensor3"
              type "infra-red"
            }
            DEF lineSensor4 DistanceSensor {
              translation -6.74634e-14 0.1 -0.05
              rotation 0 1 0 1.5708
              name "lineSensor4"
              type "infra-red"
            }
            DEF lineSensor5 DistanceSensor {
              translation 0.01 0.1 -0.05
              rotation 0 1 0 1.5708
              name "lineSensor5"
              type "infra-red"
            }
            DEF lineSensor6 DistanceSensor {
              translation 0.02 0.1 -0.05
              rotation 0 1 0 1.5708
              name "lineSensor6"
              type "infra-red"
            }
            DEF lineSensor7 DistanceSensor {
              translation 0.03 0.1 -0.05
              rotation 0 1 0 1.5708
              name "lineSensor7"
              type "infra-red"
            }
          ]
        }
        Solid {
          translation 0 0.08 -0.045
          children [
            DEF caster_shape Shape {
              appearance PBRAppearance {
              }
              geometry Capsule {
                height 0.03
                radius 0.01
              }
            }
          ]
          name "caster_wheel"
          boundingObject USE caster_shape
          physics Physics {
          }
        }
        DEF left_wheel HingeJoint {
          jointParameters HingeJointParameters {
            anchor 0 -0.01 -0.04
          }
          device [
            RotationalMotor {
              name "left_motor"
              maxTorque 50
            }
          ]
          endPoint Solid {
            translation -0.1 -0.01 -0.04
            rotation 0 -0.9999999999999999 0 1.5707953071795862
            children [
              DEF left_wheel_shape Shape {
                appearance PBRAppearance {
                  baseColor 0.127687 1 0.838727
                  roughness 1
                  metalness 0
                }
                geometry Cylinder {
                  height 0.01
                  radius 0.03
                }
              }
            ]
            boundingObject USE left_wheel_shape
            physics Physics {
            }
          }
        }
        DEF right_wheel HingeJoint {
          jointParameters HingeJointParameters {
            anchor 0 -0.01 -0.04
          }
          device [
            RotationalMotor {
              name "right_motor"
              maxTorque 50
            }
          ]
          endPoint Solid {
            translation 0.1 -0.010000000000000002 -0.04
            rotation 1.4252501626753387e-07 -0.9999999999999796 -1.4367923625557603e-07 1.570795709917693
            children [
              DEF right_wheel_shape Shape {
                appearance PBRAppearance {
                  baseColor 0.127687 1 0.838727
                  roughness 1
                  metalness 0
                }
                geometry Cylinder {
                  height 0.01
                  radius 0.03
                }
              }
            ]
            name "solid(1)"
            boundingObject USE right_wheel_shape
            physics Physics {
            }
          }
        }
        DEF body_box Shape {
          appearance PBRAppearance {
          }
          geometry Box {
            size 0.2 0.2 0.1
          }
        }
      ]
    }
  ]
  physics Physics {
  }
  controller "slrc24_controller"
  battery [
    0
  ]
}
Solid {
  translation 0.69 -1.91 0.08
  children [
    DEF pose1_cylinder_shape Shape {
      appearance PBRAppearance {
        metalness 0
      }
      geometry Cylinder {
        height 0.15
        radius 0.03
      }
    }
  ]
  name "pose1_cylinder"
  boundingObject USE pose1_cylinder_shape
  physics Physics {
  }
}
Solid {
  translation -0.64 -1.89 0.08
  children [
    DEF pose2_cuboid_shape Shape {
      appearance PBRAppearance {
        metalness 0
      }
      geometry Box {
        size 0.07 0.07 0.15
      }
    }
  ]
  name "pose2_cuboid"
  boundingObject USE pose2_cuboid_shape
  physics Physics {
  }
}
